Workbook
Name armor: _values!$F$3:$F$7
Name blocking: _values!$O$3:$O$4
Name bludgeoning: _values!$L$3:$L$4
Name channeling: _values!$P$3:$P$4
Name consumable: _values!$G$3:$G$10
Name goods: _values!$H$3:$H$8
Name hacking: _values!$J$3:$J$4
Name heavy: _values!$T$3:$T$6
Name infusing: _values!$R$3:$R$10
Name light: _values!$V$3:$V$6
Name material: _values!$S$3:$S$17
Name medium: _values!$U$3:$U$6
Name miscellaneous: _values!$X$3:$X$6
Name profession: _values!$Z$3:$Z$4
Name projectile: _values!$N$3:$N$4
Name skill: _values!$Y$3:$Y$4
Name slashing: _values!$K$3:$K$4
Name thrusting: _values!$M$3:$M$4
Name trinket: _values!$W$3:$W$6
Name warding: _values!$Q$3:$Q$4
Name weapon: _values!$E$3:$E$12

Sheet items
A1: item_id | B1: template | C1: tts_type | D1: set | E1: name | F1: type | G1: subtype | H1: subsubtype | I1: tier | J1: stat | K1: damage_range | L1: damage_type | M1: damage_range2 | N1: damage_type2 | O1: armor_range | P1: armor_type | Q1: armor_range2 | R1: armor_type2 | S1: base_gold | T1: effect | U1: flavor | V1: cooldown | W1: uses | X1: gmnotes | Y1: image_front | Z1: image_back
A2: IT1 | B2: item_template | C2: tile | D2: mining | E2: Amberstone | F2: goods | G2: material | H2: ore | I2: 0 | J2: =IF(G2="","",IFERROR(IF(G2="infusing",IFERROR(LOOKUP(2,1/ISNUMBER(SEARCH(_lookup!$D$3:$D$4,H2)),_lookup!$E$3:$E$4),"INT"),VLOOKUP(G2,_lookup!$A$3:$B$14,2,FALSE)),"")) | K2: =IF(F2<>"weapon","",IF(G2="miscellaneous","1-4",IF(I2="","",IFERROR(VLOOKUP(I2&"|"&IF(LEFT(H2,2)="2H",2,1)&"|"&IF(G2="slashing",1,0),_lookup!$G$3:$H$18,2,FALSE),"")))) | L2: =IF(K2="","",IF(OR(G2="channeling",G2="infusing"),"Magical",IF(G2="blocking","Anti-Physical",IF(G2="warding","Anti-Magical","Physical")))) | O2: =IF(F2<>"armor","","TBD") | P2: =IF(O2="","",IF(OR(G2="channeling",G2="infusing"),"Magical",IF(G2="blocking","Anti-Physical",IF(G2="warding","Anti-Magical","Physical")))) | S2: 3 | T2: Used to craft tier 0 Weaponsmithing weapons or Armorsmithing heavy armors and shields. | U2: Native to the Woodland, these copper stones have a unique, malleable property that make it useful for fashioning daily equipment. | X2: ore0 | Y2: https://drive.google.com/uc?export=download&id=1_a5uwrAod6Ng8GkAQa3DsRShH7UxdQ3W
A3: IT2 | B3: item_template | C3: tile | D3: mining | E3: Mill Copper | F3: goods | G3: material | H3: ore | I3: 0 | J3: =IF(G3="","",IFERROR(IF(G3="infusing",IFERROR(LOOKUP(2,1/ISNUMBER(SEARCH(_lookup!$D$3:$D$4,H3)),_lookup!$E$3:$E$4),"INT"),VLOOKUP(G3,_lookup!$A$3:$B$14,2,FALSE)),"")) | K3: =IF(F3<>"weapon","",IF(G3="miscellaneous","1-4",IF(I3="","",IFERROR(VLOOKUP(I3&"|"&IF(LEFT(H3,2)="2H",2,1)&"|"&IF(G3="slashing",1,0),_lookup!$G$3:$H$18,2,FALSE),"")))) | L3: =IF(K3="","",IF(OR(G3="channeling",G3="infusing"),"Magical",IF(G3="blocking","Anti-Physical",IF(G3="warding","Anti-Magical","Physical")))) | O3: =IF(F3<>"armor","","TBD") | P3: =IF(O3="","",IF(OR(G3="channeling",G3="infusing"),"Magical",IF(G3="blocking","Anti-Physical",IF(G3="warding","Anti-Magical","Physical")))) | S3: 3 | T3: Used to craft tier 0 Weaponsmithing weapons or Armorsmithing heavy armors and shields. | U3: Stamped by the Marquisate mills, this mass-produced metal rivals the reliability of Amberstone. | X3: ore0 | Y3: https://drive.google.com/uc?export=download&id=1utBTnuoZ1QIfLl264KWZbkUl7HtMo3__
A4: IT3 | B4: item_template | C4: tile | D4: mining | E4: Burrow Iron | F4: goods | G4: material | H4: ore | I4: 1 | J4: =IF(G4="","",IFERROR(IF(G4="infusing",IFERROR(LOOKUP(2,1/ISNUMBER(SEARCH(_lookup!$D$3:$D$4,H4)),_lookup!$E$3:$E$4),"INT"),VLOOKUP(G4,_lookup!$A$3:$B$14,2,FALSE)),"")) | K4: =IF(F4<>"weapon","",IF(G4="miscellaneous","1-4",IF(I4="","",IFERROR(VLOOKUP(I4&"|"&IF(LEFT(H4,2)="2H",2,1)&"|"&IF(G4="slashing",1,0),_lookup!$G$3:$H$18,2,FALSE),"")))) | L4: =IF(K4="","",IF(OR(G4="channeling",G4="infusing"),"Magical",IF(G4="blocking","Anti-Physical",IF(G4="warding","Anti-Magical","Physical")))) | O4: =IF(F4<>"armor","","TBD") | P4: =IF(O4="","",IF(OR(G4="channeling",G4="infusing"),"Magical",IF(G4="blocking","Anti-Physical",IF(G4="warding","Anti-Magical","Physical")))) | S4: 9 | T4: Used to craft tier 1 Weaponsmithing weapons or Armorsmithing heavy armors and shields. | U4: Named after the faction that first dug it up, this cold ore smells faintly of damp autumn soil. | X4: ore1 | Y4: https://drive.google.com/uc?export=download&id=1ngYo7TzWaQswib4wWAreW-3JV09wUrTB
A5: IT4 | B5: item_template | C5: tile | D5: mining | E5: Mill Iron | F5: goods | G5: material | H5: ore | I5: 1 | J5: =IF(G5="","",IFERROR(IF(G5="infusing",IFERROR(LOOKUP(2,1/ISNUMBER(SEARCH(_lookup!$D$3:$D$4,H5)),_lookup!$E$3:$E$4),"INT"),VLOOKUP(G5,_lookup!$A$3:$B$14,2,FALSE)),"")) | K5: =IF(F5<>"weapon","",IF(G5="miscellaneous","1-4",IF(I5="","",IFERROR(VLOOKUP(I5&"|"&IF(LEFT(H5,2)="2H",2,1)&"|"&IF(G5="slashing",1,0),_lookup!$G$3:$H$18,2,FALSE),"")))) | L5: =IF(K5="","",IF(OR(G5="channeling",G5="infusing"),"Magical",IF(G5="blocking","Anti-Physical",IF(G5="warding","Anti-Magical","Physical")))) | O5: =IF(F5<>"armor","","TBD") | P5: =IF(O5="","",IF(OR(G5="channeling",G5="infusing"),"Magical",IF(G5="blocking","Anti-Physical",IF(G5="warding","Anti-Magical","Physical")))) | S5: 9 | T5: Used to craft tier 1 Weaponsmithing weapons or Armorsmithing heavy armors and shields. | U5: While famously known as the signature metal of the Marquisate's armies, its production remains a guarded industrial secret. | X5: ore1 | Y5: https://drive.google.com/uc?export=download&id=1ik08EUjvQBwmTu2MCJ9eBEgpCMer-RsD
A6: IT5 | B6: item_template | C6: tile | D6: mining | E6: Silver | F6: goods | G6: material | H6: ore | I6: 2 | J6: =IF(G6="","",IFERROR(IF(G6="infusing",IFERROR(LOOKUP(2,1/ISNUMBER(SEARCH(_lookup!$D$3:$D$4,H6)),_lookup!$E$3:$E$4),"INT"),VLOOKUP(G6,_lookup!$A$3:$B$14,2,FALSE)),"")) | K6: =IF(F6<>"weapon","",IF(G6="miscellaneous","1-4",IF(I6="","",IFERROR(VLOOKUP(I6&"|"&IF(LEFT(H6,2)="2H",2,1)&"|"&IF(G6="slashing",1,0),_lookup!$G$3:$H$18,2,FALSE),"")))) | L6: =IF(K6="","",IF(OR(G6="channeling",G6="infusing"),"Magical",IF(G6="blocking","Anti-Physical",IF(G6="warding","Anti-Magical","Physical")))) | O6: =IF(F6<>"armor","","TBD") | P6: =IF(O6="","",IF(OR(G6="channeling",G6="infusing"),"Magical",IF(G6="blocking","Anti-Physical",IF(G6="warding","Anti-Magical","Physical")))) | S6: 36 | T6: Used to craft tier 2 Weaponsmithing weapons or Armorsmithing heavy armors and shields. | U6: A precious metal used by ambitious factions to mint coin, purchase allegiance, or forge elegant symbols of authority. | X6: ore2 | Y6: https://drive.google.com/uc?export=download&id=1PyM4XzjeZTvJQX1KdQBtY19XcTxg5pQG
A7: IT6 | B7: item_template | C7: tile | D7: mining | E7: Eyriesteel | F7: goods | G7: material | H7: ore | I7: 2 | J7: =IF(G7="","",IFERROR(IF(G7="infusing",IFERROR(LOOKUP(2,1/ISNUMBER(SEARCH(_lookup!$D$3:$D$4,H7)),_lookup!$E$3:$E$4),"INT"),VLOOKUP(G7,_lookup!$A$3:$B$14,2,FALSE)),"")) | K7: =IF(F7<>"weapon","",IF(G7="miscellaneous","1-4",IF(I7="","",IFERROR(VLOOKUP(I7&"|"&IF(LEFT(H7,2)="2H",2,1)&"|"&IF(G7="slashing",1,0),_lookup!$G$3:$H$18,2,FALSE),"")))) | L7: =IF(K7="","",IF(OR(G7="channeling",G7="infusing"),"Magical",IF(G7="blocking","Anti-Physical",IF(G7="warding","Anti-Magical","Physical")))) | O7: =IF(F7<>"armor","","TBD") | P7: =IF(O7="","",IF(OR(G7="channeling",G7="infusing"),"Magical",IF(G7="blocking","Anti-Physical",IF(G7="warding","Anti-Magical","Physical")))) | S7: 36 | T7: Used to craft tier 2 Weaponsmithing weapons or Armorsmithing heavy armors and shields. | U7: Regally strong, this polished metal reflects the unyielding pride and ancient military might of the Eyrie Dynasty. | X7: ore2 | Y7: https://drive.google.com/uc?export=download&id=1Ep8L_2uiKNnMTI0qXFN616lI61R_amWD
A8: IT7 | B8: item_template | C8: tile | D8: mining | E8: Truesilver | F8: goods | G8: material | H8: ore | I8: 3 | J8: =IF(G8="","",IFERROR(IF(G8="infusing",IFERROR(LOOKUP(2,1/ISNUMBER(SEARCH(_lookup!$D$3:$D$4,H8)),_lookup!$E$3:$E$4),"INT"),VLOOKUP(G8,_lookup!$A$3:$B$14,2,FALSE)),"")) | K8: =IF(F8<>"weapon","",IF(G8="miscellaneous","1-4",IF(I8="","",IFERROR(VLOOKUP(I8&"|"&IF(LEFT(H8,2)="2H",2,1)&"|"&IF(G8="slashing",1,0),_lookup!$G$3:$H$18,2,FALSE),"")))) | L8: =IF(K8="","",IF(OR(G8="channeling",G8="infusing"),"Magical",IF(G8="blocking","Anti-Physical",IF(G8="warding","Anti-Magical","Physical")))) | O8: =IF(F8<>"armor","","TBD") | P8: =IF(O8="","",IF(OR(G8="channeling",G8="infusing"),"Magical",IF(G8="blocking","Anti-Physical",IF(G8="warding","Anti-Magical","Physical")))) | S8: 100 | T8: Used to craft tier 3 Weaponsmithing weapons or Armorsmithing heavy armors and shields. | U8: A legendary, moon-bright metal sought by every faction, whispered to be as light as a feather yet stronger than tempered steel. | X8: ore3 | Y8: https://drive.google.com/uc?export=download&id=1CgdIHu46YReFdMGO-Kogmq45HmG5cPoj
A9: IT8 | B9: item_template | C9: tile | D9: mining | E9: Truesilver Bar | F9: goods | G9: material | H9: ore | I9: 3 | J9: =IF(G9="","",IFERROR(IF(G9="infusing",IFERROR(LOOKUP(2,1/ISNUMBER(SEARCH(_lookup!$D$3:$D$4,H9)),_lookup!$E$3:$E$4),"INT"),VLOOKUP(G9,_lookup!$A$3:$B$14,2,FALSE)),"")) | K9: =IF(F9<>"weapon","",IF(G9="miscellaneous","1-4",IF(I9="","",IFERROR(VLOOKUP(I9&"|"&IF(LEFT(H9,2)="2H",2,1)&"|"&IF(G9="slashing",1,0),_lookup!$G$3:$H$18,2,FALSE),"")))) | L9: =IF(K9="","",IF(OR(G9="channeling",G9="infusing"),"Magical",IF(G9="blocking","Anti-Physical",IF(G9="warding","Anti-Magical","Physical")))) | O9: =IF(F9<>"armor","","TBD") | P9: =IF(O9="","",IF(OR(G9="channeling",G9="infusing"),"Magical",IF(G9="blocking","Anti-Physical",IF(G9="warding","Anti-Magical","Physical")))) | S9: 100 | T9: Used to craft tier 3 Weaponsmithing weapons or Armorsmithing heavy armors and shields. | U9: A flawlessly smelted bar of legendary metal, glowing with a faint inner light and ready to be forged into the woodland’s greatest relics. | X9: ore3 | Y9: https://drive.google.com/uc?export=download&id=1PVzqT1xPogQa9KufxHWpg17296Y7fV5P
A10: IT9 | B10: item_template | C10: tile | D10: mining | E10: Riverglass | F10: goods | G10: material | H10: gem | I10: 0 | J10: =IF(G10="","",IFERROR(IF(G10="infusing",IFERROR(LOOKUP(2,1/ISNUMBER(SEARCH(_lookup!$D$3:$D$4,H10)),_lookup!$E$3:$E$4),"INT"),VLOOKUP(G10,_lookup!$A$3:$B$14,2,FALSE)),"")) | K10: =IF(F10<>"weapon","",IF(G10="miscellaneous","1-4",IF(I10="","",IFERROR(VLOOKUP(I10&"|"&IF(LEFT(H10,2)="2H",2,1)&"|"&IF(G10="slashing",1,0),_lookup!$G$3:$H$18,2,FALSE),"")))) | L10: =IF(K10="","",IF(OR(G10="channeling",G10="infusing"),"Magical",IF(G10="blocking","Anti-Physical",IF(G10="warding","Anti-Magical","Physical")))) | O10: =IF(F10<>"armor","","TBD") | P10: =IF(O10="","",IF(OR(G10="channeling",G10="infusing"),"Magical",IF(G10="blocking","Anti-Physical",IF(G10="warding","Anti-Magical","Physical")))) | S10: 3 | T10: Used to craft tier 0 Jewelcrafting trinkets. | U10: Despite its smooth and polished appearance, this green gem is only found within ore veins, often far from the water. | X10: gem0 | Y10: https://drive.google.com/uc?export=download&id=1SLregdXIDHCXrahi4M1eLyB2G7hsAlr_
A11: IT10 | B11: item_template | C11: tile | D11: mining | E11: Deep Quartz | F11: goods | G11: material | H11: gem | I11: 1 | J11: =IF(G11="","",IFERROR(IF(G11="infusing",IFERROR(LOOKUP(2,1/ISNUMBER(SEARCH(_lookup!$D$3:$D$4,H11)),_lookup!$E$3:$E$4),"INT"),VLOOKUP(G11,_lookup!$A$3:$B$14,2,FALSE)),"")) | K11: =IF(F11<>"weapon","",IF(G11="miscellaneous","1-4",IF(I11="","",IFERROR(VLOOKUP(I11&"|"&IF(LEFT(H11,2)="2H",2,1)&"|"&IF(G11="slashing",1,0),_lookup!$G$3:$H$18,2,FALSE),"")))) | L11: =IF(K11="","",IF(OR(G11="channeling",G11="infusing"),"Magical",IF(G11="blocking","Anti-Physical",IF(G11="warding","Anti-Magical","Physical")))) | O11: =IF(F11<>"armor","","TBD") | P11: =IF(O11="","",IF(OR(G11="channeling",G11="infusing"),"Magical",IF(G11="blocking","Anti-Physical",IF(G11="warding","Anti-Magical","Physical")))) | S11: 11 | T11: Used to craft tier 1 Jewelcrafting trinkets. | U11: A bright, yellow crystal mined from the suffocatingly deep caverns of the world. | X11: gem1 | Y11: https://drive.google.com/uc?export=download&id=1ZAWydmErIxi5antngVWsFLGzcV1cFaEW
A12: IT11 | B12: item_template | C12: tile | D12: mining | E12: Royal Ruby | F12: goods | G12: material | H12: gem | I12: 2 | J12: =IF(G12="","",IFERROR(IF(G12="infusing",IFERROR(LOOKUP(2,1/ISNUMBER(SEARCH(_lookup!$D$3:$D$4,H12)),_lookup!$E$3:$E$4),"INT"),VLOOKUP(G12,_lookup!$A$3:$B$14,2,FALSE)),"")) | K12: =IF(F12<>"weapon","",IF(G12="miscellaneous","1-4",IF(I12="","",IFERROR(VLOOKUP(I12&"|"&IF(LEFT(H12,2)="2H",2,1)&"|"&IF(G12="slashing",1,0),_lookup!$G$3:$H$18,2,FALSE),"")))) | L12: =IF(K12="","",IF(OR(G12="channeling",G12="infusing"),"Magical",IF(G12="blocking","Anti-Physical",IF(G12="warding","Anti-Magical","Physical")))) | O12: =IF(F12<>"armor","","TBD") | P12: =IF(O12="","",IF(OR(G12="channeling",G12="infusing"),"Magical",IF(G12="blocking","Anti-Physical",IF(G12="warding","Anti-Magical","Physical")))) | S12: 45 | T12: Used to craft tier 2 Jewelcrafting trinkets. | U12: Fiercely fought over by aristocratic factions, this brilliant ruby is the ultimate symbol of high status and sovereign authority. | X12: gem2 | Y12: https://drive.google.com/uc?export=download&id=1p7mkkzdnHjzNSexVphkU4wE8FwjGdry-
A13: IT12 | B13: item_template | C13: tile | D13: mining | E13: Shadowgem | F13: goods | G13: material | H13: gem | I13: 3 | J13: =IF(G13="","",IFERROR(IF(G13="infusing",IFERROR(LOOKUP(2,1/ISNUMBER(SEARCH(_lookup!$D$3:$D$4,H13)),_lookup!$E$3:$E$4),"INT"),VLOOKUP(G13,_lookup!$A$3:$B$14,2,FALSE)),"")) | K13: =IF(F13<>"weapon","",IF(G13="miscellaneous","1-4",IF(I13="","",IFERROR(VLOOKUP(I13&"|"&IF(LEFT(H13,2)="2H",2,1)&"|"&IF(G13="slashing",1,0),_lookup!$G$3:$H$18,2,FALSE),"")))) | L13: =IF(K13="","",IF(OR(G13="channeling",G13="infusing"),"Magical",IF(G13="blocking","Anti-Physical",IF(G13="warding","Anti-Magical","Physical")))) | O13: =IF(F13<>"armor","","TBD") | P13: =IF(O13="","",IF(OR(G13="channeling",G13="infusing"),"Magical",IF(G13="blocking","Anti-Physical",IF(G13="warding","Anti-Magical","Physical")))) | S13: 125 | T13: Used to craft tier 3 Jewelcrafting trinkets. | U13: A deep purple stone that seems to swallow the light. Its uses are unknown, but its beauty entices even the most cautious buyers. | X13: gem3 | Y13: https://drive.google.com/uc?export=download&id=1siJAXuly8GOoukB583JgRkYSBZDqg0QV
A14: IT13 | B14: item_template | C14: tile | D14: mining | E14: Moonstone | F14: goods | G14: material | H14: gem | I14: 3 | J14: =IF(G14="","",IFERROR(IF(G14="infusing",IFERROR(LOOKUP(2,1/ISNUMBER(SEARCH(_lookup!$D$3:$D$4,H14)),_lookup!$E$3:$E$4),"INT"),VLOOKUP(G14,_lookup!$A$3:$B$14,2,FALSE)),"")) | K14: =IF(F14<>"weapon","",IF(G14="miscellaneous","1-4",IF(I14="","",IFERROR(VLOOKUP(I14&"|"&IF(LEFT(H14,2)="2H",2,1)&"|"&IF(G14="slashing",1,0),_lookup!$G$3:$H$18,2,FALSE),"")))) | L14: =IF(K14="","",IF(OR(G14="channeling",G14="infusing"),"Magical",IF(G14="blocking","Anti-Physical",IF(G14="warding","Anti-Magical","Physical")))) | O14: =IF(F14<>"armor","","TBD") | P14: =IF(O14="","",IF(OR(G14="channeling",G14="infusing"),"Magical",IF(G14="blocking","Anti-Physical",IF(G14="warding","Anti-Magical","Physical")))) | S14: 125 | T14: Used to craft tier 3 Jewelcrafting trinkets. | U14: A glowing cyan gem that mirrors the cold night sky, said by woodland mystics to bring good fortune to those who travel after dark. | X14: gem3 | Y14: https://drive.google.com/uc?export=download&id=1KMimIV61oBYMt06wuK8LXmVNmKWxE81S
A15: IT14 | B15: item_template | C15: tile | D15: mining | E15: Rock | F15: goods | G15: junk | I15: 0 | J15: =IF(G15="","",IFERROR(IF(G15="infusing",IFERROR(LOOKUP(2,1/ISNUMBER(SEARCH(_lookup!$D$3:$D$4,H15)),_lookup!$E$3:$E$4),"INT"),VLOOKUP(G15,_lookup!$A$3:$B$14,2,FALSE)),"")) | K15: =IF(F15<>"weapon","",IF(G15="miscellaneous","1-4",IF(I15="","",IFERROR(VLOOKUP(I15&"|"&IF(LEFT(H15,2)="2H",2,1)&"|"&IF(G15="slashing",1,0),_lookup!$G$3:$H$18,2,FALSE),"")))) | L15: =IF(K15="","",IF(OR(G15="channeling",G15="infusing"),"Magical",IF(G15="blocking","Anti-Physical",IF(G15="warding","Anti-Magical","Physical")))) | O15: =IF(F15<>"armor","","TBD") | P15: =IF(O15="","",IF(OR(G15="channeling",G15="infusing"),"Magical",IF(G15="blocking","Anti-Physical",IF(G15="warding","Anti-Magical","Physical")))) | S15: 1 | U15: A rock. You picked it up for reasons that made sense at the time. | Y15: https://drive.google.com/uc?export=download&id=1i2FgUyYLCZM8BGwJVtbr_G4ddVMsojMw
A16: IT15 | B16: item_template | C16: tile | D16: mining | E16: Rough Stone | F16: goods | G16: material | H16: stone | I16: 0 | J16: =IF(G16="","",IFERROR(IF(G16="infusing",IFERROR(LOOKUP(2,1/ISNUMBER(SEARCH(_lookup!$D$3:$D$4,H16)),_lookup!$E$3:$E$4),"INT"),VLOOKUP(G16,_lookup!$A$3:$B$14,2,FALSE)),"")) | K16: =IF(F16<>"weapon","",IF(G16="miscellaneous","1-4",IF(I16="","",IFERROR(VLOOKUP(I16&"|"&IF(LEFT(H16,2)="2H",2,1)&"|"&IF(G16="slashing",1,0),_lookup!$G$3:$H$18,2,FALSE),"")))) | L16: =IF(K16="","",IF(OR(G16="channeling",G16="infusing"),"Magical",IF(G16="blocking","Anti-Physical",IF(G16="warding","Anti-Magical","Physical")))) | O16: =IF(F16<>"armor","","TBD") | P16: =IF(O16="","",IF(OR(G16="channeling",G16="infusing"),"Magical",IF(G16="blocking","Anti-Physical",IF(G16="warding","Anti-Magical","Physical")))) | S16: 3 | T16: Used to craft tier 0 Weaponsmithing weapon stones. | U16: Coarse grey stone split straight from the quarry face. It takes an edge off as readily as it puts one on, so a careful paw works slowly. | X16: stone0 | Y16: https://drive.google.com/uc?export=download&id=1lW6Ehhvsy3-32O3sSrPRxfiDzNOp1Dq5
A17: IT16 | B17: item_template | C17: tile | D17: mining | E17: Coarse Stone | F17: goods | G17: material | H17: stone | I17: 1 | J17: =IF(G17="","",IFERROR(IF(G17="infusing",IFERROR(LOOKUP(2,1/ISNUMBER(SEARCH(_lookup!$D$3:$D$4,H17)),_lookup!$E$3:$E$4),"INT"),VLOOKUP(G17,_lookup!$A$3:$B$14,2,FALSE)),"")) | K17: =IF(F17<>"weapon","",IF(G17="miscellaneous","1-4",IF(I17="","",IFERROR(VLOOKUP(I17&"|"&IF(LEFT(H17,2)="2H",2,1)&"|"&IF(G17="slashing",1,0),_lookup!$G$3:$H$18,2,FALSE),"")))) | L17: =IF(K17="","",IF(OR(G17="channeling",G17="infusing"),"Magical",IF(G17="blocking","Anti-Physical",IF(G17="warding","Anti-Magical","Physical")))) | O17: =IF(F17<>"armor","","TBD") | P17: =IF(O17="","",IF(OR(G17="channeling",G17="infusing"),"Magical",IF(G17="blocking","Anti-Physical",IF(G17="warding","Anti-Magical","Physical")))) | S17: 9 | T17: Used to craft tier 1 Weaponsmithing weapon stones. | U17: Denser than it looks, and even in the grain. The smiths of the mill towns keep a block of it on every bench. | X17: stone1 | Y17: https://drive.google.com/uc?export=download&id=18sWc_nBl9Vmjl2_Nsmcy5QDc4kILOETK
A18: IT17 | B18: item_template | C18: tile | D18: mining | E18: Heavy Stone | F18: goods | G18: material | H18: stone | I18: 2 | J18: =IF(G18="","",IFERROR(IF(G18="infusing",IFERROR(LOOKUP(2,1/ISNUMBER(SEARCH(_lookup!$D$3:$D$4,H18)),_lookup!$E$3:$E$4),"INT"),VLOOKUP(G18,_lookup!$A$3:$B$14,2,FALSE)),"")) | K18: =IF(F18<>"weapon","",IF(G18="miscellaneous","1-4",IF(I18="","",IFERROR(VLOOKUP(I18&"|"&IF(LEFT(H18,2)="2H",2,1)&"|"&IF(G18="slashing",1,0),_lookup!$G$3:$H$18,2,FALSE),"")))) | L18: =IF(K18="","",IF(OR(G18="channeling",G18="infusing"),"Magical",IF(G18="blocking","Anti-Physical",IF(G18="warding","Anti-Magical","Physical")))) | O18: =IF(F18<>"armor","","TBD") | P18: =IF(O18="","",IF(OR(G18="channeling",G18="infusing"),"Magical",IF(G18="blocking","Anti-Physical",IF(G18="warding","Anti-Magical","Physical")))) | S18: 36 | T18: Used to craft tier 2 Weaponsmithing weapon stones. | U18: Dark and close-grained, heavy enough to sit still while you work. It will outlast several of the blades it sharpens. | X18: stone2 | Y18: https://drive.google.com/uc?export=download&id=16vqvGwB_FpMS9k7lDVnC8POZoi0l-zHQ
A19: IT18 | B19: item_template | C19: tile | D19: mining | E19: Desne Stone | F19: goods | G19: material | H19: stone | I19: 3 | J19: =IF(G19="","",IFERROR(IF(G19="infusing",IFERROR(LOOKUP(2,1/ISNUMBER(SEARCH(_lookup!$D$3:$D$4,H19)),_lookup!$E$3:$E$4),"INT"),VLOOKUP(G19,_lookup!$A$3:$B$14,2,FALSE)),"")) | K19: =IF(F19<>"weapon","",IF(G19="miscellaneous","1-4",IF(I19="","",IFERROR(VLOOKUP(I19&"|"&IF(LEFT(H19,2)="2H",2,1)&"|"&IF(G19="slashing",1,0),_lookup!$G$3:$H$18,2,FALSE),"")))) | L19: =IF(K19="","",IF(OR(G19="channeling",G19="infusing"),"Magical",IF(G19="blocking","Anti-Physical",IF(G19="warding","Anti-Magical","Physical")))) | O19: =IF(F19<>"armor","","TBD") | P19: =IF(O19="","",IF(OR(G19="channeling",G19="infusing"),"Magical",IF(G19="blocking","Anti-Physical",IF(G19="warding","Anti-Magical","Physical")))) | S19: 100 | T19: Used to craft tier 3 Weaponsmithing weapon stones. | U19: So fine it feels almost soft, and so dense it rings faintly when struck. A single block is handed down through a family of smiths. | X19: stone3 | Y19: https://drive.google.com/uc?export=download&id=12CazpWZAx-ecXZNdvz10G9TFVwmyy5Wc
A20: IT19 | B20: item_template | C20: tile | D20: mining | E20: Pickaxe | F20: weapon | G20: miscellaneous | H20: 1H | I20: 0 | J20: =IF(G20="","",IFERROR(IF(G20="infusing",IFERROR(LOOKUP(2,1/ISNUMBER(SEARCH(_lookup!$D$3:$D$4,H20)),_lookup!$E$3:$E$4),"INT"),VLOOKUP(G20,_lookup!$A$3:$B$14,2,FALSE)),"")) | K20: =IF(F20<>"weapon","",IF(G20="miscellaneous","1-4",IF(I20="","",IFERROR(VLOOKUP(I20&"|"&IF(LEFT(H20,2)="2H",2,1)&"|"&IF(G20="slashing",1,0),_lookup!$G$3:$H$18,2,FALSE),"")))) | L20: =IF(K20="","",IF(OR(G20="channeling",G20="infusing"),"Magical",IF(G20="blocking","Anti-Physical",IF(G20="warding","Anti-Magical","Physical")))) | O20: =IF(F20<>"armor","","TBD") | P20: =IF(O20="","",IF(OR(G20="channeling",G20="infusing"),"Magical",IF(G20="blocking","Anti-Physical",IF(G20="warding","Anti-Magical","Physical")))) | S20: 12 | T20: Doubles the loot of level 0 Mining. This does not stack. | U20: A hazel haft and a head beaten out of whatever iron was going spare. It chips more than it cuts, but it has opened a great many first seams. | X20: dmg:1-4|Physical|miscellaneous | Y20: https://drive.google.com/uc?export=download&id=1C75A1-Rr1kWdn_JGCnLf0vE6cxIA1Wgt
A21: IT20 | B21: item_template | C21: tile | D21: mining | E21: Sturdy Pickaxe | F21: weapon | G21: miscellaneous | H21: 1H | I21: 1 | J21: =IF(G21="","",IFERROR(IF(G21="infusing",IFERROR(LOOKUP(2,1/ISNUMBER(SEARCH(_lookup!$D$3:$D$4,H21)),_lookup!$E$3:$E$4),"INT"),VLOOKUP(G21,_lookup!$A$3:$B$14,2,FALSE)),"")) | K21: =IF(F21<>"weapon","",IF(G21="miscellaneous","1-4",IF(I21="","",IFERROR(VLOOKUP(I21&"|"&IF(LEFT(H21,2)="2H",2,1)&"|"&IF(G21="slashing",1,0),_lookup!$G$3:$H$18,2,FALSE),"")))) | L21: =IF(K21="","",IF(OR(G21="channeling",G21="infusing"),"Magical",IF(G21="blocking","Anti-Physical",IF(G21="warding","Anti-Magical","Physical")))) | O21: =IF(F21<>"armor","","TBD") | P21: =IF(O21="","",IF(OR(G21="channeling",G21="infusing"),"Magical",IF(G21="blocking","Anti-Physical",IF(G21="warding","Anti-Magical","Physical")))) | S21: 36 | T21: Doubles the loot of level 0 or 1 Mining. This does not stack. | U21: Properly hafted and properly balanced, with a head that stays on through a full day's swinging. The difference is felt by evening. | X21: dmg:1-4|Physical|miscellaneous | Y21: https://drive.google.com/uc?export=download&id=1W74uQeIeIk4mdCbKxrQK66Aa2BMzZWUY
A22: IT21 | B22: item_template | C22: tile | D22: mining | E22: Steel Pickaxe | F22: weapon | G22: miscellaneous | H22: 1H | I22: 2 | J22: =IF(G22="","",IFERROR(IF(G22="infusing",IFERROR(LOOKUP(2,1/ISNUMBER(SEARCH(_lookup!$D$3:$D$4,H22)),_lookup!$E$3:$E$4),"INT"),VLOOKUP(G22,_lookup!$A$3:$B$14,2,FALSE)),"")) | K22: =IF(F22<>"weapon","",IF(G22="miscellaneous","1-4",IF(I22="","",IFERROR(VLOOKUP(I22&"|"&IF(LEFT(H22,2)="2H",2,1)&"|"&IF(G22="slashing",1,0),_lookup!$G$3:$H$18,2,FALSE),"")))) | L22: =IF(K22="","",IF(OR(G22="channeling",G22="infusing"),"Magical",IF(G22="blocking","Anti-Physical",IF(G22="warding","Anti-Magical","Physical")))) | O22: =IF(F22<>"armor","","TBD") | P22: =IF(O22="","",IF(OR(G22="channeling",G22="infusing"),"Magical",IF(G22="blocking","Anti-Physical",IF(G22="warding","Anti-Magical","Physical")))) | S22: 144 | T22: Doubles the loot of level 0, 1, or 2 Mining. This does not stack. | U22: Forged head, steel-shod haft, and an edge that holds through the hard grey rock the cheaper tools simply bounce off. | X22: dmg:1-4|Physical|miscellaneous | Y22: https://drive.google.com/uc?export=download&id=156tkg64DYbARVYfwMzaHZCyCNHRd5vkX
A23: IT22 | B23: item_template | C23: tile | D23: mining | E23: Gold Bar | F23: goods | G23: material | H23: ore | I23: 0 | J23: =IF(G23="","",IFERROR(IF(G23="infusing",IFERROR(LOOKUP(2,1/ISNUMBER(SEARCH(_lookup!$D$3:$D$4,H23)),_lookup!$E$3:$E$4),"INT"),VLOOKUP(G23,_lookup!$A$3:$B$14,2,FALSE)),"")) | K23: =IF(F23<>"weapon","",IF(G23="miscellaneous","1-4",IF(I23="","",IFERROR(VLOOKUP(I23&"|"&IF(LEFT(H23,2)="2H",2,1)&"|"&IF(G23="slashing",1,0),_lookup!$G$3:$H$18,2,FALSE),"")))) | L23: =IF(K23="","",IF(OR(G23="channeling",G23="infusing"),"Magical",IF(G23="blocking","Anti-Physical",IF(G23="warding","Anti-Magical","Physical")))) | O23: =IF(F23<>"armor","","TBD") | P23: =IF(O23="","",IF(OR(G23="channeling",G23="infusing"),"Magical",IF(G23="blocking","Anti-Physical",IF(G23="warding","Anti-Magical","Physical")))) | S23: 3 | T23: Used to craft tier 0 Weaponsmithing weapons or Armorsmithing armors and shields. | U23: Prized more for its sheen rather than its strength, this metal is often hoarded by bandits and denizens alike. | X23: ore0 | Y23: https://drive.google.com/uc?export=download&id=1LcrFpOzopAuiZVZyq7-K2NfqTfrc3Dlm
A24: IT23 | B24: item_template | C24: tile | D24: fishing | E24: Ribbon Clam | F24: consumable | G24: lootbox | I24: 0 | J24: =IF(G24="","",IFERROR(IF(G24="infusing",IFERROR(LOOKUP(2,1/ISNUMBER(SEARCH(_lookup!$D$3:$D$4,H24)),_lookup!$E$3:$E$4),"INT"),VLOOKUP(G24,_lookup!$A$3:$B$14,2,FALSE)),"")) | K24: =IF(F24<>"weapon","",IF(G24="miscellaneous","1-4",IF(I24="","",IFERROR(VLOOKUP(I24&"|"&IF(LEFT(H24,2)="2H",2,1)&"|"&IF(G24="slashing",1,0),_lookup!$G$3:$H$18,2,FALSE),"")))) | L24: =IF(K24="","",IF(OR(G24="channeling",G24="infusing"),"Magical",IF(G24="blocking","Anti-Physical",IF(G24="warding","Anti-Magical","Physical")))) | O24: =IF(F24<>"armor","","TBD") | P24: =IF(O24="","",IF(OR(G24="channeling",G24="infusing"),"Magical",IF(G24="blocking","Anti-Physical",IF(G24="warding","Anti-Magical","Physical")))) | S24: 4 | T24: Flip over to open. | U24: A palm-sized clam, its shell banded like a ribbon. Riverfolk say a clam that closes hard on your paw is hiding something worth the pinch. | Y24: https://drive.google.com/uc?export=download&id=1jLljsRHWVFLSLmL2wVhVAiEnDxTCYmat
A25: IT24 | B25: item_template | C25: tile | D25: fishing | E25: Deepwater Clam | F25: consumable | G25: lootbox | I25: 1 | J25: =IF(G25="","",IFERROR(IF(G25="infusing",IFERROR(LOOKUP(2,1/ISNUMBER(SEARCH(_lookup!$D$3:$D$4,H25)),_lookup!$E$3:$E$4),"INT"),VLOOKUP(G25,_lookup!$A$3:$B$14,2,FALSE)),"")) | K25: =IF(F25<>"weapon","",IF(G25="miscellaneous","1-4",IF(I25="","",IFERROR(VLOOKUP(I25&"|"&IF(LEFT(H25,2)="2H",2,1)&"|"&IF(G25="slashing",1,0),_lookup!$G$3:$H$18,2,FALSE),"")))) | L25: =IF(K25="","",IF(OR(G25="channeling",G25="infusing"),"Magical",IF(G25="blocking","Anti-Physical",IF(G25="warding","Anti-Magical","Physical")))) | O25: =IF(F25<>"armor","","TBD") | P25: =IF(O25="","",IF(OR(G25="channeling",G25="infusing"),"Magical",IF(G25="blocking","Anti-Physical",IF(G25="warding","Anti-Magical","Physical")))) | S25: 14 | T25: Flip over to open. | U25: Hauled up from the cold water under the mill race. The shell is mottled purple and heavy, and the older the clam, the better what sleeps inside it. | Y25: https://drive.google.com/uc?export=download&id=1YYPIwvmQBpEtqisHN9smHdGF8RjjstP2
A26: IT25 | B26: item_template | C26: tile | D26: fishing | E26: Clam Meat | F26: consumable | G26: food | I26: 0 | J26: =IF(G26="","",IFERROR(IF(G26="infusing",IFERROR(LOOKUP(2,1/ISNUMBER(SEARCH(_lookup!$D$3:$D$4,H26)),_lookup!$E$3:$E$4),"INT"),VLOOKUP(G26,_lookup!$A$3:$B$14,2,FALSE)),"")) | K26: =IF(F26<>"weapon","",IF(G26="miscellaneous","1-4",IF(I26="","",IFERROR(VLOOKUP(I26&"|"&IF(LEFT(H26,2)="2H",2,1)&"|"&IF(G26="slashing",1,0),_lookup!$G$3:$H$18,2,FALSE),"")))) | L26: =IF(K26="","",IF(OR(G26="channeling",G26="infusing"),"Magical",IF(G26="blocking","Anti-Physical",IF(G26="warding","Anti-Magical","Physical")))) | O26: =IF(F26<>"armor","","TBD") | P26: =IF(O26="","",IF(OR(G26="channeling",G26="infusing"),"Magical",IF(G26="blocking","Anti-Physical",IF(G26="warding","Anti-Magical","Physical")))) | S26: 4 | T26: Eat in multiples of 3 to prevent Hunger. | U26: Often likened to the berry of the roads, this pale meat is cold and faintly sweet. | Y26: https://drive.google.com/uc?export=download&id=1l77jjhX0xbrrO5NH6orftp-1r8AOMVsH
A27: IT26 | B27: item_template | C27: tile | D27: fishing | E27: Silverfin | F27: goods | G27: material | H27: fish | I27: 0 | J27: =IF(G27="","",IFERROR(IF(G27="infusing",IFERROR(LOOKUP(2,1/ISNUMBER(SEARCH(_lookup!$D$3:$D$4,H27)),_lookup!$E$3:$E$4),"INT"),VLOOKUP(G27,_lookup!$A$3:$B$14,2,FALSE)),"")) | K27: =IF(F27<>"weapon","",IF(G27="miscellaneous","1-4",IF(I27="","",IFERROR(VLOOKUP(I27&"|"&IF(LEFT(H27,2)="2H",2,1)&"|"&IF(G27="slashing",1,0),_lookup!$G$3:$H$18,2,FALSE),"")))) | L27: =IF(K27="","",IF(OR(G27="channeling",G27="infusing"),"Magical",IF(G27="blocking","Anti-Physical",IF(G27="warding","Anti-Magical","Physical")))) | O27: =IF(F27<>"armor","","TBD") | P27: =IF(O27="","",IF(OR(G27="channeling",G27="infusing"),"Magical",IF(G27="blocking","Anti-Physical",IF(G27="warding","Anti-Magical","Physical")))) | S27: 3 | T27: Used to craft tier 0 Survival foods. | U27: The common fish of every slow stretch of water in the Woodland. Bony, plentiful, and the first thing any young angler ever lands. | X27: fish0 | Y27: https://drive.google.com/uc?export=download&id=13rpwHAHwWb6g6guEtgOTpKaHzCZJ5htX
A28: IT27 | B28: item_template | C28: tile | D28: fishing | E28: Rushpike | F28: goods | G28: material | H28: fish | I28: 1 | J28: =IF(G28="","",IFERROR(IF(G28="infusing",IFERROR(LOOKUP(2,1/ISNUMBER(SEARCH(_lookup!$D$3:$D$4,H28)),_lookup!$E$3:$E$4),"INT"),VLOOKUP(G28,_lookup!$A$3:$B$14,2,FALSE)),"")) | K28: =IF(F28<>"weapon","",IF(G28="miscellaneous","1-4",IF(I28="","",IFERROR(VLOOKUP(I28&"|"&IF(LEFT(H28,2)="2H",2,1)&"|"&IF(G28="slashing",1,0),_lookup!$G$3:$H$18,2,FALSE),"")))) | L28: =IF(K28="","",IF(OR(G28="channeling",G28="infusing"),"Magical",IF(G28="blocking","Anti-Physical",IF(G28="warding","Anti-Magical","Physical")))) | O28: =IF(F28<>"armor","","TBD") | P28: =IF(O28="","",IF(OR(G28="channeling",G28="infusing"),"Magical",IF(G28="blocking","Anti-Physical",IF(G28="warding","Anti-Magical","Physical")))) | S28: 9 | T28: Used to craft tier 1 Survival foods. | U28: A lean hunter of the reed beds, all jaw and bad temper. It takes a bait meant for something smaller and fights the whole way in. | X28: fish1 | Y28: https://drive.google.com/uc?export=download&id=1Cyjh7d39M6ecUK7-kwXtU7OsnfVi4nU1
A29: IT28 | B29: item_template | C29: tile | D29: fishing | E29: Greenback Trout | F29: goods | G29: material | H29: fish | I29: 2 | J29: =IF(G29="","",IFERROR(IF(G29="infusing",IFERROR(LOOKUP(2,1/ISNUMBER(SEARCH(_lookup!$D$3:$D$4,H29)),_lookup!$E$3:$E$4),"INT"),VLOOKUP(G29,_lookup!$A$3:$B$14,2,FALSE)),"")) | K29: =IF(F29<>"weapon","",IF(G29="miscellaneous","1-4",IF(I29="","",IFERROR(VLOOKUP(I29&"|"&IF(LEFT(H29,2)="2H",2,1)&"|"&IF(G29="slashing",1,0),_lookup!$G$3:$H$18,2,FALSE),"")))) | L29: =IF(K29="","",IF(OR(G29="channeling",G29="infusing"),"Magical",IF(G29="blocking","Anti-Physical",IF(G29="warding","Anti-Magical","Physical")))) | O29: =IF(F29<>"armor","","TBD") | P29: =IF(O29="","",IF(OR(G29="channeling",G29="infusing"),"Magical",IF(G29="blocking","Anti-Physical",IF(G29="warding","Anti-Magical","Physical")))) | S29: 36 | T29: Used to craft tier 2 Survival foods. | U29: Thick through the shoulder and green as wet moss. Found only where the water runs cold and fast, which is rarely where it is safe to stand. | X29: fish2 | Y29: https://drive.google.com/uc?export=download&id=1HTbXRjtegmWyeBCzsCMgxAzevJFXSYrm
A30: IT29 | B30: item_template | C30: tile | D30: fishing | E30: Gloomfish | F30: goods | G30: material | H30: fish | I30: 3 | J30: =IF(G30="","",IFERROR(IF(G30="infusing",IFERROR(LOOKUP(2,1/ISNUMBER(SEARCH(_lookup!$D$3:$D$4,H30)),_lookup!$E$3:$E$4),"INT"),VLOOKUP(G30,_lookup!$A$3:$B$14,2,FALSE)),"")) | K30: =IF(F30<>"weapon","",IF(G30="miscellaneous","1-4",IF(I30="","",IFERROR(VLOOKUP(I30&"|"&IF(LEFT(H30,2)="2H",2,1)&"|"&IF(G30="slashing",1,0),_lookup!$G$3:$H$18,2,FALSE),"")))) | L30: =IF(K30="","",IF(OR(G30="channeling",G30="infusing"),"Magical",IF(G30="blocking","Anti-Physical",IF(G30="warding","Anti-Magical","Physical")))) | O30: =IF(F30<>"armor","","TBD") | P30: =IF(O30="","",IF(OR(G30="channeling",G30="infusing"),"Magical",IF(G30="blocking","Anti-Physical",IF(G30="warding","Anti-Magical","Physical")))) | S30: 100 | T30: Used to craft tier 3 Survival foods. | U30: Caught after dusk in the deep pools, its scales holding the last of the light. This large fish is prized for its taste and size. | X30: fish3 | Y30: https://drive.google.com/uc?export=download&id=13fdWAoJQ-wk9qJoyiZ_EpHCiyakU4mIR
A31: IT30 | B31: item_template | C31: tile | D31: fishing | E31: Waterlogged Letter | F31: consumable | G31: lootbox | I31: 0 | J31: =IF(G31="","",IFERROR(IF(G31="infusing",IFERROR(LOOKUP(2,1/ISNUMBER(SEARCH(_lookup!$D$3:$D$4,H31)),_lookup!$E$3:$E$4),"INT"),VLOOKUP(G31,_lookup!$A$3:$B$14,2,FALSE)),"")) | K31: =IF(F31<>"weapon","",IF(G31="miscellaneous","1-4",IF(I31="","",IFERROR(VLOOKUP(I31&"|"&IF(LEFT(H31,2)="2H",2,1)&"|"&IF(G31="slashing",1,0),_lookup!$G$3:$H$18,2,FALSE),"")))) | L31: =IF(K31="","",IF(OR(G31="channeling",G31="infusing"),"Magical",IF(G31="blocking","Anti-Physical",IF(G31="warding","Anti-Magical","Physical")))) | O31: =IF(F31<>"armor","","TBD") | P31: =IF(O31="","",IF(OR(G31="channeling",G31="infusing"),"Magical",IF(G31="blocking","Anti-Physical",IF(G31="warding","Anti-Magical","Physical")))) | S31: 4 | T31: Flip over to open. | U31: Something lost to the river a long time ago, and finally given back. The paper comes apart in your paws. | Y31: https://drive.google.com/uc?export=download&id=1AFKkiJLx9IblKxO303EobkK1tdACk4GY
A32: IT31 | B32: item_template | C32: tile | D32: fishing | E32: Sunken Satchel | F32: consumable | G32: lootbox | I32: 1 | J32: =IF(G32="","",IFERROR(IF(G32="infusing",IFERROR(LOOKUP(2,1/ISNUMBER(SEARCH(_lookup!$D$3:$D$4,H32)),_lookup!$E$3:$E$4),"INT"),VLOOKUP(G32,_lookup!$A$3:$B$14,2,FALSE)),"")) | K32: =IF(F32<>"weapon","",IF(G32="miscellaneous","1-4",IF(I32="","",IFERROR(VLOOKUP(I32&"|"&IF(LEFT(H32,2)="2H",2,1)&"|"&IF(G32="slashing",1,0),_lookup!$G$3:$H$18,2,FALSE),"")))) | L32: =IF(K32="","",IF(OR(G32="channeling",G32="infusing"),"Magical",IF(G32="blocking","Anti-Physical",IF(G32="warding","Anti-Magical","Physical")))) | O32: =IF(F32<>"armor","","TBD") | P32: =IF(O32="","",IF(OR(G32="channeling",G32="infusing"),"Magical",IF(G32="blocking","Anti-Physical",IF(G32="warding","Anti-Magical","Physical")))) | S32: 14 | T32: Flip over to open. | U32: Still buckled, still holding. Whoever packed it meant to come back for it. | Y32: https://drive.google.com/uc?export=download&id=1F3cAA2jPU-gkfyvTYxlBq3tJBfBgQz5b
A33: IT32 | B33: item_template | C33: tile | D33: fishing | E33: Banded Crate | F33: consumable | G33: lootbox | I33: 2 | J33: =IF(G33="","",IFERROR(IF(G33="infusing",IFERROR(LOOKUP(2,1/ISNUMBER(SEARCH(_lookup!$D$3:$D$4,H33)),_lookup!$E$3:$E$4),"INT"),VLOOKUP(G33,_lookup!$A$3:$B$14,2,FALSE)),"")) | K33: =IF(F33<>"weapon","",IF(G33="miscellaneous","1-4",IF(I33="","",IFERROR(VLOOKUP(I33&"|"&IF(LEFT(H33,2)="2H",2,1)&"|"&IF(G33="slashing",1,0),_lookup!$G$3:$H$18,2,FALSE),"")))) | L33: =IF(K33="","",IF(OR(G33="channeling",G33="infusing"),"Magical",IF(G33="blocking","Anti-Physical",IF(G33="warding","Anti-Magical","Physical")))) | O33: =IF(F33<>"armor","","TBD") | P33: =IF(O33="","",IF(OR(G33="channeling",G33="infusing"),"Magical",IF(G33="blocking","Anti-Physical",IF(G33="warding","Anti-Magical","Physical")))) | S33: 41 | T33: Flip over to open. | U33: Iron bands over dark wood, the lock long since rusted through. Marquisate work, by the stamp on the hasp. | Y33: https://drive.google.com/uc?export=download&id=1Lx27boIuKuMOt6zFcd0GOoBiRBuvZKg3
A34: IT33 | B34: item_template | C34: tile | D34: fishing | E34: Riverbed Chest | F34: consumable | G34: lootbox | I34: 3 | J34: =IF(G34="","",IFERROR(IF(G34="infusing",IFERROR(LOOKUP(2,1/ISNUMBER(SEARCH(_lookup!$D$3:$D$4,H34)),_lookup!$E$3:$E$4),"INT"),VLOOKUP(G34,_lookup!$A$3:$B$14,2,FALSE)),"")) | K34: =IF(F34<>"weapon","",IF(G34="miscellaneous","1-4",IF(I34="","",IFERROR(VLOOKUP(I34&"|"&IF(LEFT(H34,2)="2H",2,1)&"|"&IF(G34="slashing",1,0),_lookup!$G$3:$H$18,2,FALSE),"")))) | L34: =IF(K34="","",IF(OR(G34="channeling",G34="infusing"),"Magical",IF(G34="blocking","Anti-Physical",IF(G34="warding","Anti-Magical","Physical")))) | O34: =IF(F34<>"armor","","TBD") | P34: =IF(O34="","",IF(OR(G34="channeling",G34="infusing"),"Magical",IF(G34="blocking","Anti-Physical",IF(G34="warding","Anti-Magical","Physical")))) | S34: 79 | T34: Flip over to open. | U34: Heavy, and sealed well enough that the water never got in. Something was worth hiding at the bottom of a river. | Y34: https://drive.google.com/uc?export=download&id=1oLVZXSecu_g4a3gjEdhBEEmwNBn0MeVx
A35: IT34 | B35: item_template | C35: tile | D35: fishing | E35: Wax-Sealed Backpack | F35: goods | G35: miscellaneous | J35: =IF(G35="","",IFERROR(IF(G35="infusing",IFERROR(LOOKUP(2,1/ISNUMBER(SEARCH(_lookup!$D$3:$D$4,H35)),_lookup!$E$3:$E$4),"INT"),VLOOKUP(G35,_lookup!$A$3:$B$14,2,FALSE)),"")) | K35: =IF(F35<>"weapon","",IF(G35="miscellaneous","1-4",IF(I35="","",IFERROR(VLOOKUP(I35&"|"&IF(LEFT(H35,2)="2H",2,1)&"|"&IF(G35="slashing",1,0),_lookup!$G$3:$H$18,2,FALSE),"")))) | L35: =IF(K35="","",IF(OR(G35="channeling",G35="infusing"),"Magical",IF(G35="blocking","Anti-Physical",IF(G35="warding","Anti-Magical","Physical")))) | O35: =IF(F35<>"armor","","TBD") | P35: =IF(O35="","",IF(OR(G35="channeling",G35="infusing"),"Magical",IF(G35="blocking","Anti-Physical",IF(G35="warding","Anti-Magical","Physical")))) | T35: Expands inventory by 6. | U35: Dry and good-as-new, this pack seems to have been mistakenly lost to water along some Riverfolk trade route. | Y35: https://drive.google.com/uc?export=download&id=1O3TmbtOtYNRd66h1NsbUH-LMfTUP0okT
A36: IT35 | B36: item_template | C36: tile | D36: fishing | E36: Crab Trap | F36: consumable | G36: lootbox | I36: 0 | J36: =IF(G36="","",IFERROR(IF(G36="infusing",IFERROR(LOOKUP(2,1/ISNUMBER(SEARCH(_lookup!$D$3:$D$4,H36)),_lookup!$E$3:$E$4),"INT"),VLOOKUP(G36,_lookup!$A$3:$B$14,2,FALSE)),"")) | K36: =IF(F36<>"weapon","",IF(G36="miscellaneous","1-4",IF(I36="","",IFERROR(VLOOKUP(I36&"|"&IF(LEFT(H36,2)="2H",2,1)&"|"&IF(G36="slashing",1,0),_lookup!$G$3:$H$18,2,FALSE),"")))) | L36: =IF(K36="","",IF(OR(G36="channeling",G36="infusing"),"Magical",IF(G36="blocking","Anti-Physical",IF(G36="warding","Anti-Magical","Physical")))) | O36: =IF(F36<>"armor","","TBD") | P36: =IF(O36="","",IF(OR(G36="channeling",G36="infusing"),"Magical",IF(G36="blocking","Anti-Physical",IF(G36="warding","Anti-Magical","Physical")))) | S36: 4 | T36: Flip over to open. | U36: A slatted basket weighted with stones and baited with whatever was going spare. Left overnight in the shallows, it is never quite empty by morning. | Y36: https://drive.google.com/uc?export=download&id=15oYc5zZbsdafWF3cZKVy5vq8mUw1kwAO
A37: IT36 | B37: item_template | C37: tile | D37: fishing | E37: Mysterious Key | F37: goods | G37: quest | J37: =IF(G37="","",IFERROR(IF(G37="infusing",IFERROR(LOOKUP(2,1/ISNUMBER(SEARCH(_lookup!$D$3:$D$4,H37)),_lookup!$E$3:$E$4),"INT"),VLOOKUP(G37,_lookup!$A$3:$B$14,2,FALSE)),"")) | K37: =IF(F37<>"weapon","",IF(G37="miscellaneous","1-4",IF(I37="","",IFERROR(VLOOKUP(I37&"|"&IF(LEFT(H37,2)="2H",2,1)&"|"&IF(G37="slashing",1,0),_lookup!$G$3:$H$18,2,FALSE),"")))) | L37: =IF(K37="","",IF(OR(G37="channeling",G37="infusing"),"Magical",IF(G37="blocking","Anti-Physical",IF(G37="warding","Anti-Magical","Physical")))) | O37: =IF(F37<>"armor","","TBD") | P37: =IF(O37="","",IF(OR(G37="channeling",G37="infusing"),"Magical",IF(G37="blocking","Anti-Physical",IF(G37="warding","Anti-Magical","Physical")))) | T37: Starts the "Mysterious Key" Quest. | U37: Small, cold, and far better made than anything that ought to turn up in a river. The bow is worked into a shape you do not recognise, and the wards fit no lock you have ever seen. | Y37: https://drive.google.com/uc?export=download&id=1B6pMRRQiEzoBH8KaPW0leoi8yldUVdpT
A38: IT37 | B38: item_template | C38: tile | D38: fishing | E38: Lustrous Pearl | F38: goods | G38: material | H38: gem | I38: 0 | J38: =IF(G38="","",IFERROR(IF(G38="infusing",IFERROR(LOOKUP(2,1/ISNUMBER(SEARCH(_lookup!$D$3:$D$4,H38)),_lookup!$E$3:$E$4),"INT"),VLOOKUP(G38,_lookup!$A$3:$B$14,2,FALSE)),"")) | K38: =IF(F38<>"weapon","",IF(G38="miscellaneous","1-4",IF(I38="","",IFERROR(VLOOKUP(I38&"|"&IF(LEFT(H38,2)="2H",2,1)&"|"&IF(G38="slashing",1,0),_lookup!$G$3:$H$18,2,FALSE),"")))) | L38: =IF(K38="","",IF(OR(G38="channeling",G38="infusing"),"Magical",IF(G38="blocking","Anti-Physical",IF(G38="warding","Anti-Magical","Physical")))) | O38: =IF(F38<>"armor","","TBD") | P38: =IF(O38="","",IF(OR(G38="channeling",G38="infusing"),"Magical",IF(G38="blocking","Anti-Physical",IF(G38="warding","Anti-Magical","Physical")))) | S38: 3 | T38: Used to craft tier 0 Jewelcrafting trinkets. | U38: A small, honest pearl with a clean white shine. Common enough along the river, and still the first thing a young clam-diver shows their family. | X38: gem0 | Y38: https://drive.google.com/uc?export=download&id=1QmxvfYCTwjWCpgVgBgrZq5i7IjzVrYDu
A39: IT38 | B39: item_template | C39: tile | D39: fishing | E39: Iridescent Pearl | F39: goods | G39: material | H39: gem | I39: 1 | J39: =IF(G39="","",IFERROR(IF(G39="infusing",IFERROR(LOOKUP(2,1/ISNUMBER(SEARCH(_lookup!$D$3:$D$4,H39)),_lookup!$E$3:$E$4),"INT"),VLOOKUP(G39,_lookup!$A$3:$B$14,2,FALSE)),"")) | K39: =IF(F39<>"weapon","",IF(G39="miscellaneous","1-4",IF(I39="","",IFERROR(VLOOKUP(I39&"|"&IF(LEFT(H39,2)="2H",2,1)&"|"&IF(G39="slashing",1,0),_lookup!$G$3:$H$18,2,FALSE),"")))) | L39: =IF(K39="","",IF(OR(G39="channeling",G39="infusing"),"Magical",IF(G39="blocking","Anti-Physical",IF(G39="warding","Anti-Magical","Physical")))) | O39: =IF(F39<>"armor","","TBD") | P39: =IF(O39="","",IF(OR(G39="channeling",G39="infusing"),"Magical",IF(G39="blocking","Anti-Physical",IF(G39="warding","Anti-Magical","Physical")))) | S39: 11 | T39: Used to craft tier 1 Jewelcrafting trinkets. | U39: It holds a faint rainbow at the edge of the light, as though it has not quite decided on a colour. Jewellers pay well and argue about why. | X39: gem1 | Y39: https://drive.google.com/uc?export=download&id=1jOc6uiqfr3_6za1mvr7nPbBtR0UqnaSg
A40: IT39 | B40: item_template | C40: tile | D40: fishing | E40: Golden Pearl | F40: goods | G40: material | H40: gem | I40: 2 | J40: =IF(G40="","",IFERROR(IF(G40="infusing",IFERROR(LOOKUP(2,1/ISNUMBER(SEARCH(_lookup!$D$3:$D$4,H40)),_lookup!$E$3:$E$4),"INT"),VLOOKUP(G40,_lookup!$A$3:$B$14,2,FALSE)),"")) | K40: =IF(F40<>"weapon","",IF(G40="miscellaneous","1-4",IF(I40="","",IFERROR(VLOOKUP(I40&"|"&IF(LEFT(H40,2)="2H",2,1)&"|"&IF(G40="slashing",1,0),_lookup!$G$3:$H$18,2,FALSE),"")))) | L40: =IF(K40="","",IF(OR(G40="channeling",G40="infusing"),"Magical",IF(G40="blocking","Anti-Physical",IF(G40="warding","Anti-Magical","Physical")))) | O40: =IF(F40<>"armor","","TBD") | P40: =IF(O40="","",IF(OR(G40="channeling",G40="infusing"),"Magical",IF(G40="blocking","Anti-Physical",IF(G40="warding","Anti-Magical","Physical")))) | S40: 45 | T40: Used to craft tier 2 Jewelcrafting trinkets. | U40: Warm as lamplight and twice as rare. The Eyrie court is said to prize these above gemstones, which has done nothing good for the clam beds. | X40: gem2 | Y40: https://drive.google.com/uc?export=download&id=1QBmNqi2YFALNftHUymcf2jPH9h8Wrs6Z
...

Sheet skills
A1: item_id | B1: template | C1: tts_type | D1: set | E1: name | F1: type | G1: subtype | H1: subsubtype | I1: tier | J1: stat | K1: damage_range | L1: damage_type | M1: damage_range2 | N1: damage_type2 | O1: armor_range | P1: armor_type | Q1: armor_range2 | R1: armor_type2 | S1: base_gold | T1: effect | U1: flavor | V1: cooldown | W1: uses | X1: gmnotes | Y1: image_front | Z1: image_back
A2: SK1 | B2: item_template | C2: tile | D2: skills | E2: Novice Armorsmithing | F2: skill | G2: profession | H2: crafting | I2: 0 | J2: =IF(G2="","",IFERROR(IF(G2="infusing",IFERROR(LOOKUP(2,1/ISNUMBER(SEARCH(_lookup!$D$3:$D$4,H2)),_lookup!$E$3:$E$4),"INT"),VLOOKUP(G2,_lookup!$A$3:$B$14,2,FALSE)),"")) | K2: =IF(F2<>"weapon","",IF(G2="miscellaneous","1-4",IF(I2="","",IFERROR(VLOOKUP(I2&"|"&IF(LEFT(H2,2)="2H",2,1)&"|"&IF(G2="slashing",1,0),_lookup!$G$3:$H$18,2,FALSE),"")))) | L2: =IF(K2="","",IF(OR(G2="channeling",G2="infusing"),"Magical",IF(G2="blocking","Anti-Physical",IF(G2="warding","Anti-Magical","Physical")))) | O2: =IF(F2<>"armor","","TBD") | P2: =IF(O2="","",IF(OR(G2="channeling",G2="infusing"),"Magical",IF(G2="blocking","Anti-Physical",IF(G2="warding","Anti-Magical","Physical")))) | S2: 24 | T2: Turns ore into tier-specific heavy armor and blocking weapons. | U2: You can beat a plate flat and rivet it to a strap. It will turn a claw, mostly, and the straps will hold for a season. | Y2: https://drive.google.com/uc?export=download&id=19fHlCGroOvRb89QfIU7LrQrB90peJuqj
A3: SK2 | B3: item_template | C3: tile | D3: skills | E3: Journeyman Armorsmithing | F3: skill | G3: profession | H3: crafting | I3: 1 | J3: =IF(G3="","",IFERROR(IF(G3="infusing",IFERROR(LOOKUP(2,1/ISNUMBER(SEARCH(_lookup!$D$3:$D$4,H3)),_lookup!$E$3:$E$4),"INT"),VLOOKUP(G3,_lookup!$A$3:$B$14,2,FALSE)),"")) | K3: =IF(F3<>"weapon","",IF(G3="miscellaneous","1-4",IF(I3="","",IFERROR(VLOOKUP(I3&"|"&IF(LEFT(H3,2)="2H",2,1)&"|"&IF(G3="slashing",1,0),_lookup!$G$3:$H$18,2,FALSE),"")))) | L3: =IF(K3="","",IF(OR(G3="channeling",G3="infusing"),"Magical",IF(G3="blocking","Anti-Physical",IF(G3="warding","Anti-Magical","Physical")))) | O3: =IF(F3<>"armor","","TBD") | P3: =IF(O3="","",IF(OR(G3="channeling",G3="infusing"),"Magical",IF(G3="blocking","Anti-Physical",IF(G3="warding","Anti-Magical","Physical")))) | S3: 72 | T3: Turns ore into tier-specific heavy armor and blocking weapons. | U3: You have learned where armor actually fails: the gaps, the hinges, the places a blow travels through. Yours fail there less often. | Y3: https://drive.google.com/uc?export=download&id=19fHlCGroOvRb89QfIU7LrQrB90peJuqj
A4: SK3 | B4: item_template | C4: tile | D4: skills | E4: Artisan Armorsmithing | F4: skill | G4: profession | H4: crafting | I4: 2 | J4: =IF(G4="","",IFERROR(IF(G4="infusing",IFERROR(LOOKUP(2,1/ISNUMBER(SEARCH(_lookup!$D$3:$D$4,H4)),_lookup!$E$3:$E$4),"INT"),VLOOKUP(G4,_lookup!$A$3:$B$14,2,FALSE)),"")) | K4: =IF(F4<>"weapon","",IF(G4="miscellaneous","1-4",IF(I4="","",IFERROR(VLOOKUP(I4&"|"&IF(LEFT(H4,2)="2H",2,1)&"|"&IF(G4="slashing",1,0),_lookup!$G$3:$H$18,2,FALSE),"")))) | L4: =IF(K4="","",IF(OR(G4="channeling",G4="infusing"),"Magical",IF(G4="blocking","Anti-Physical",IF(G4="warding","Anti-Magical","Physical")))) | O4: =IF(F4<>"armor","","TBD") | P4: =IF(O4="","",IF(OR(G4="channeling",G4="infusing"),"Magical",IF(G4="blocking","Anti-Physical",IF(G4="warding","Anti-Magical","Physical")))) | S4: 288 | T4: Turns ore into tier-specific heavy armor and blocking weapons. | U4: Your plate is shaped to the body that will wear it, and the joints move as the wearer does. Soldiers ask for you by name. | Y4: https://drive.google.com/uc?export=download&id=19fHlCGroOvRb89QfIU7LrQrB90peJuqj
A5: SK4 | B5: item_template | C5: tile | D5: skills | E5: Master Armorsmithing | F5: skill | G5: profession | H5: crafting | I5: 3 | J5: =IF(G5="","",IFERROR(IF(G5="infusing",IFERROR(LOOKUP(2,1/ISNUMBER(SEARCH(_lookup!$D$3:$D$4,H5)),_lookup!$E$3:$E$4),"INT"),VLOOKUP(G5,_lookup!$A$3:$B$14,2,FALSE)),"")) | K5: =IF(F5<>"weapon","",IF(G5="miscellaneous","1-4",IF(I5="","",IFERROR(VLOOKUP(I5&"|"&IF(LEFT(H5,2)="2H",2,1)&"|"&IF(G5="slashing",1,0),_lookup!$G$3:$H$18,2,FALSE),"")))) | L5: =IF(K5="","",IF(OR(G5="channeling",G5="infusing"),"Magical",IF(G5="blocking","Anti-Physical",IF(G5="warding","Anti-Magical","Physical")))) | O5: =IF(F5<>"armor","","TBD") | P5: =IF(O5="","",IF(OR(G5="channeling",G5="infusing"),"Magical",IF(G5="blocking","Anti-Physical",IF(G5="warding","Anti-Magical","Physical")))) | S5: 800 | T5: Turns ore into tier-specific heavy armor and blocking weapons. | U5: You work the hard ores others set aside, and what comes off your bench is handed down rather than replaced. Few smiths in the Woodland can match it. | Y5: https://drive.google.com/uc?export=download&id=19fHlCGroOvRb89QfIU7LrQrB90peJuqj
A6: SK5 | B6: item_template | C6: tile | D6: skills | E6: Novice Attuning | F6: skill | G6: profession | H6: crafting | I6: 0 | J6: =IF(G6="","",IFERROR(IF(G6="infusing",IFERROR(LOOKUP(2,1/ISNUMBER(SEARCH(_lookup!$D$3:$D$4,H6)),_lookup!$E$3:$E$4),"INT"),VLOOKUP(G6,_lookup!$A$3:$B$14,2,FALSE)),"")) | K6: =IF(F6<>"weapon","",IF(G6="miscellaneous","1-4",IF(I6="","",IFERROR(VLOOKUP(I6&"|"&IF(LEFT(H6,2)="2H",2,1)&"|"&IF(G6="slashing",1,0),_lookup!$G$3:$H$18,2,FALSE),"")))) | L6: =IF(K6="","",IF(OR(G6="channeling",G6="infusing"),"Magical",IF(G6="blocking","Anti-Physical",IF(G6="warding","Anti-Magical","Physical")))) | O6: =IF(F6<>"armor","","TBD") | P6: =IF(O6="","",IF(OR(G6="channeling",G6="infusing"),"Magical",IF(G6="blocking","Anti-Physical",IF(G6="warding","Anti-Magical","Physical")))) | S6: 24 | T6: Turns fiber and seeds into tier-specific infusions and spell-dust. | U6: You can extract just enough magic from the flora's fibers to hold an infusion. When held, its light is faint and the binding loose, but it is yours. | Y6: https://drive.google.com/uc?export=download&id=1H-H68vYBLXccnjOnVscyZiHF4LvNpLU9
A7: SK6 | B7: item_template | C7: tile | D7: skills | E7: Journeyman Attuning | F7: skill | G7: profession | H7: crafting | I7: 1 | J7: =IF(G7="","",IFERROR(IF(G7="infusing",IFERROR(LOOKUP(2,1/ISNUMBER(SEARCH(_lookup!$D$3:$D$4,H7)),_lookup!$E$3:$E$4),"INT"),VLOOKUP(G7,_lookup!$A$3:$B$14,2,FALSE)),"")) | K7: =IF(F7<>"weapon","",IF(G7="miscellaneous","1-4",IF(I7="","",IFERROR(VLOOKUP(I7&"|"&IF(LEFT(H7,2)="2H",2,1)&"|"&IF(G7="slashing",1,0),_lookup!$G$3:$H$18,2,FALSE),"")))) | L7: =IF(K7="","",IF(OR(G7="channeling",G7="infusing"),"Magical",IF(G7="blocking","Anti-Physical",IF(G7="warding","Anti-Magical","Physical")))) | O7: =IF(F7<>"armor","","TBD") | P7: =IF(O7="","",IF(OR(G7="channeling",G7="infusing"),"Magical",IF(G7="blocking","Anti-Physical",IF(G7="warding","Anti-Magical","Physical")))) | S7: 72 | T7: Turns fiber and seeds into tier-specific infusions and spell-dust. | U7: The fiber no longer fights you. You can hold a charge steady long enough to shape it into something a wielder will actually trust. | Y7: https://drive.google.com/uc?export=download&id=1H-H68vYBLXccnjOnVscyZiHF4LvNpLU9
A8: SK7 | B8: item_template | C8: tile | D8: skills | E8: Artisan Attuning | F8: skill | G8: profession | H8: crafting | I8: 2 | J8: =IF(G8="","",IFERROR(IF(G8="infusing",IFERROR(LOOKUP(2,1/ISNUMBER(SEARCH(_lookup!$D$3:$D$4,H8)),_lookup!$E$3:$E$4),"INT"),VLOOKUP(G8,_lookup!$A$3:$B$14,2,FALSE)),"")) | K8: =IF(F8<>"weapon","",IF(G8="miscellaneous","1-4",IF(I8="","",IFERROR(VLOOKUP(I8&"|"&IF(LEFT(H8,2)="2H",2,1)&"|"&IF(G8="slashing",1,0),_lookup!$G$3:$H$18,2,FALSE),"")))) | L8: =IF(K8="","",IF(OR(G8="channeling",G8="infusing"),"Magical",IF(G8="blocking","Anti-Physical",IF(G8="warding","Anti-Magical","Physical")))) | O8: =IF(F8<>"armor","","TBD") | P8: =IF(O8="","",IF(OR(G8="channeling",G8="infusing"),"Magical",IF(G8="blocking","Anti-Physical",IF(G8="warding","Anti-Magical","Physical")))) | S8: 288 | T8: Turns fiber and seeds into tier-specific infusions and spell-dust. | U8: You can concentrate magic that would burn out in another's paws, and your infusions keep their edge long after the making. | Y8: https://drive.google.com/uc?export=download&id=1H-H68vYBLXccnjOnVscyZiHF4LvNpLU9
A9: SK8 | B9: item_template | C9: tile | D9: skills | E9: Master Attuning | F9: skill | G9: profession | H9: crafting | I9: 3 | J9: =IF(G9="","",IFERROR(IF(G9="infusing",IFERROR(LOOKUP(2,1/ISNUMBER(SEARCH(_lookup!$D$3:$D$4,H9)),_lookup!$E$3:$E$4),"INT"),VLOOKUP(G9,_lookup!$A$3:$B$14,2,FALSE)),"")) | K9: =IF(F9<>"weapon","",IF(G9="miscellaneous","1-4",IF(I9="","",IFERROR(VLOOKUP(I9&"|"&IF(LEFT(H9,2)="2H",2,1)&"|"&IF(G9="slashing",1,0),_lookup!$G$3:$H$18,2,FALSE),"")))) | L9: =IF(K9="","",IF(OR(G9="channeling",G9="infusing"),"Magical",IF(G9="blocking","Anti-Physical",IF(G9="warding","Anti-Magical","Physical")))) | O9: =IF(F9<>"armor","","TBD") | P9: =IF(O9="","",IF(OR(G9="channeling",G9="infusing"),"Magical",IF(G9="blocking","Anti-Physical",IF(G9="warding","Anti-Magical","Physical")))) | S9: 800 | T9: Turns fiber and seeds into tier-specific infusions and spell-dust. | U9: What you bind does not fade. Wielders bring you their oldest infusions to have the light woken back into them. | Y9: https://drive.google.com/uc?export=download&id=1H-H68vYBLXccnjOnVscyZiHF4LvNpLU9
A10: SK9 | B10: item_template | C10: tile | D10: skills | E10: Novice Fishing | F10: skill | G10: profession | H10: gathering | I10: 0 | J10: =IF(G10="","",IFERROR(IF(G10="infusing",IFERROR(LOOKUP(2,1/ISNUMBER(SEARCH(_lookup!$D$3:$D$4,H10)),_lookup!$E$3:$E$4),"INT"),VLOOKUP(G10,_lookup!$A$3:$B$14,2,FALSE)),"")) | K10: =IF(F10<>"weapon","",IF(G10="miscellaneous","1-4",IF(I10="","",IFERROR(VLOOKUP(I10&"|"&IF(LEFT(H10,2)="2H",2,1)&"|"&IF(G10="slashing",1,0),_lookup!$G$3:$H$18,2,FALSE),"")))) | L10: =IF(K10="","",IF(OR(G10="channeling",G10="infusing"),"Magical",IF(G10="blocking","Anti-Physical",IF(G10="warding","Anti-Magical","Physical")))) | O10: =IF(F10<>"armor","","TBD") | P10: =IF(O10="","",IF(OR(G10="channeling",G10="infusing"),"Magical",IF(G10="blocking","Anti-Physical",IF(G10="warding","Anti-Magical","Physical")))) | S10: 24 | T10: Gathers fish, wraps, and various fishing treasures. | U10: You can read a bank well enough to find the slow water, and you have learned to wait. Most of what you land is small. | Y10: https://drive.google.com/uc?export=download&id=1PA6tDJuXBgsc4uRiu5k4knGngmYvei5U
A11: SK10 | B11: item_template | C11: tile | D11: skills | E11: Journeyman Fishing | F11: skill | G11: profession | H11: gathering | I11: 1 | J11: =IF(G11="","",IFERROR(IF(G11="infusing",IFERROR(LOOKUP(2,1/ISNUMBER(SEARCH(_lookup!$D$3:$D$4,H11)),_lookup!$E$3:$E$4),"INT"),VLOOKUP(G11,_lookup!$A$3:$B$14,2,FALSE)),"")) | K11: =IF(F11<>"weapon","",IF(G11="miscellaneous","1-4",IF(I11="","",IFERROR(VLOOKUP(I11&"|"&IF(LEFT(H11,2)="2H",2,1)&"|"&IF(G11="slashing",1,0),_lookup!$G$3:$H$18,2,FALSE),"")))) | L11: =IF(K11="","",IF(OR(G11="channeling",G11="infusing"),"Magical",IF(G11="blocking","Anti-Physical",IF(G11="warding","Anti-Magical","Physical")))) | O11: =IF(F11<>"armor","","TBD") | P11: =IF(O11="","",IF(OR(G11="channeling",G11="infusing"),"Magical",IF(G11="blocking","Anti-Physical",IF(G11="warding","Anti-Magical","Physical")))) | S11: 72 | T11: Gathers fish, wraps, and various fishing treasures. | U11: You know which pools hold fish at which hour, and the line no longer tangles in the reeds. The basket is rarely empty now. | Y11: https://drive.google.com/uc?export=download&id=1PA6tDJuXBgsc4uRiu5k4knGngmYvei5U
A12: SK11 | B12: item_template | C12: tile | D12: skills | E12: Artisan Fishing | F12: skill | G12: profession | H12: gathering | I12: 2 | J12: =IF(G12="","",IFERROR(IF(G12="infusing",IFERROR(LOOKUP(2,1/ISNUMBER(SEARCH(_lookup!$D$3:$D$4,H12)),_lookup!$E$3:$E$4),"INT"),VLOOKUP(G12,_lookup!$A$3:$B$14,2,FALSE)),"")) | K12: =IF(F12<>"weapon","",IF(G12="miscellaneous","1-4",IF(I12="","",IFERROR(VLOOKUP(I12&"|"&IF(LEFT(H12,2)="2H",2,1)&"|"&IF(G12="slashing",1,0),_lookup!$G$3:$H$18,2,FALSE),"")))) | L12: =IF(K12="","",IF(OR(G12="channeling",G12="infusing"),"Magical",IF(G12="blocking","Anti-Physical",IF(G12="warding","Anti-Magical","Physical")))) | O12: =IF(F12<>"armor","","TBD") | P12: =IF(O12="","",IF(OR(G12="channeling",G12="infusing"),"Magical",IF(G12="blocking","Anti-Physical",IF(G12="warding","Anti-Magical","Physical")))) | S12: 288 | T12: Gathers fish, wraps, and various fishing treasures. | U12: You fish the deep channels and the fast water others avoid, and come back with what the rest of the bank only hears about. | Y12: https://drive.google.com/uc?export=download&id=1PA6tDJuXBgsc4uRiu5k4knGngmYvei5U
A13: SK12 | B13: item_template | C13: tile | D13: skills | E13: Master Fishing | F13: skill | G13: profession | H13: gathering | I13: 3 | J13: =IF(G13="","",IFERROR(IF(G13="infusing",IFERROR(LOOKUP(2,1/ISNUMBER(SEARCH(_lookup!$D$3:$D$4,H13)),_lookup!$E$3:$E$4),"INT"),VLOOKUP(G13,_lookup!$A$3:$B$14,2,FALSE)),"")) | K13: =IF(F13<>"weapon","",IF(G13="miscellaneous","1-4",IF(I13="","",IFERROR(VLOOKUP(I13&"|"&IF(LEFT(H13,2)="2H",2,1)&"|"&IF(G13="slashing",1,0),_lookup!$G$3:$H$18,2,FALSE),"")))) | L13: =IF(K13="","",IF(OR(G13="channeling",G13="infusing"),"Magical",IF(G13="blocking","Anti-Physical",IF(G13="warding","Anti-Magical","Physical")))) | O13: =IF(F13<>"armor","","TBD") | P13: =IF(O13="","",IF(OR(G13="channeling",G13="infusing"),"Magical",IF(G13="blocking","Anti-Physical",IF(G13="warding","Anti-Magical","Physical")))) | S13: 800 | T13: Gathers fish, wraps, and various fishing treasures. | U13: There is no stretch of water in the Woodland you cannot work. What you pull from the river, the river did not intend to give up. | Y13: https://drive.google.com/uc?export=download&id=1PA6tDJuXBgsc4uRiu5k4knGngmYvei5U
... A49: SK48 | B49: item_template | C49: tile | D49: skills | E49: Master Woodworking | F49: skill | G49: profession | H49: crafting | I49: 3 | J49: =IF(G49="","",IFERROR(IF(G49="infusing",IFERROR(LOOKUP(2,1/ISNUMBER(SEARCH(_lookup!$D$3:$D$4,H49)),_lookup!$E$3:$E$4),"INT"),VLOOKUP(G49,_lookup!$A$3:$B$14,2,FALSE)),"")) | K49: =IF(F49<>"weapon","",IF(G49="miscellaneous","1-4",IF(I49="","",IFERROR(VLOOKUP(I49&"|"&IF(LEFT(H49,2)="2H",2,1)&"|"&IF(G49="slashing",1,0),_lookup!$G$3:$H$18,2,FALSE),"")))) | L49: =IF(K49="","",IF(OR(G49="channeling",G49="infusing"),"Magical",IF(G49="blocking","Anti-Physical",IF(G49="warding","Anti-Magical","Physical")))) | O49: =IF(F49<>"armor","","TBD") | P49: =IF(O49="","",IF(OR(G49="channeling",G49="infusing"),"Magical",IF(G49="blocking","Anti-Physical",IF(G49="warding","Anti-Magical","Physical")))) | S49: 800 | T49: Turns wood into tier-specific projectile and channeling weapons. | U49: Your bows are spoken of in other warrens. The limbs are thin as a reed and throw harder than anything that size has a right to. | Y49: https://drive.google.com/uc?export=download&id=1ky-Jx_5IVL7rl7GmSU8lNpS6_9ARfSBp
J50: =IF(G50="","",IFERROR(IF(G50="infusing",IFERROR(LOOKUP(2,1/ISNUMBER(SEARCH(_lookup!$D$3:$D$4,H50)),_lookup!$E$3:$E$4),"INT"),VLOOKUP(G50,_lookup!$A$3:$B$14,2,FALSE)),"")) | K50: =IF(F50<>"weapon","",IF(G50="miscellaneous","1-4",IF(I50="","",IFERROR(VLOOKUP(I50&"|"&IF(LEFT(H50,2)="2H",2,1)&"|"&IF(G50="slashing",1,0),_lookup!$G$3:$H$18,2,FALSE),"")))) | L50: =IF(K50="","",IF(OR(G50="channeling",G50="infusing"),"Magical",IF(G50="blocking","Anti-Physical",IF(G50="warding","Anti-Magical","Physical")))) | O50: =IF(F50<>"armor","","TBD") | P50: =IF(O50="","",IF(OR(G50="channeling",G50="infusing"),"Magical",IF(G50="blocking","Anti-Physical",IF(G50="warding","Anti-Magical","Physical"))))
